Workbook

Sheet 1_patient_info
A1: Patient Assessment Information
D2: Legend
A3: Patient ID: | B3: ## | D3: Required
A4: Date of Assessment: | B4: MM/DD/YYYY | D4: Optional
A5: 2nd Date of Assessment:
A6: Affected Hand | B6: Right
A7: Assessment_Phase | B7: baseline
A11: Notes: | B11: Lorem Ipsum
A22: Included Assessments | B22: Excluded Assessments
A23: 2_StrokeImpactScale | B23: 7b_MyomoTasks_WITH_MYOPRO
A24: 3_COPM | B24: 8b_CAHAI_WITH_MYOPRO
A25: 4_ModifiedAshworthScale | B25: 9b_NASA_TLX_WITH_MYOPRO
A26: 5_Fugl-Meyer | B26: 6_box_and_blocks
A27: 7a_MyomoTasks_WITHOUT_MYOPRO
A28: 8a_CAHAI_WITHOUT_MYOPRO
A29: 9a_NASA_TLX_WITHOUT_MYOPRO

Sheet NOTES
A1: Assessment | B1: Comleted? | C1: Notes | E1: Patient Info / General Notes
A2: MAS / MMT / AROM | B2: No | C2: Lorem Ipsum | E2: Lorem Ipsum
A3: Fugl-Meyer | B3: No | C3: Lorem Ipsum
A4: Stroke Impact Scale | B4: No | C4: Lorem Ipsum
A5: COPM | B5: No | C5: Lorem Ipsum
A6: Myomo Tasks W/O | B6: No | C6: Lorem Ipsum
A7: CAHAI (W/O) | B7: No | C7: Lorem Ipsum | E7: Other / Miscellaneous
A8: NASA TLX (W/O) | B8: No | C8: Lorem Ipsum | E8: Lorem Ipsum
A9: Myomo Tasks (W/) | B9: No | C9: Lorem Ipsum
A10: CAHAI (W/) | B10: No | C10: Lorem Ipsum
A11: NASA TLX (W/) | B11: No | C11: Lorem Ipsum

Sheet 2_StrokeImpactScale
A1: Stroke Impact Scale (SIS) v3.0
A3: Patient ID: | B3: ='1_patient_info'!B3 -> ## | C3: Date: | D3: MM/DD/YYYY
A5: Instructions: | B5: This scale measures health status following a stroke. The final item asks the patient to rate his or her perceived recovery on a scale of 0 to 100.
A8: 1. In the past week, how would you rate the strength of your.... | B8: A lot of strength | C8: Quite a bit of strength | D8: Some strength | E8: A little strength | F8: No strength at all | G8: Score | H8: Scaled | J8: Overall Scaled Score
A9: a. Arm that was most affected by your stroke? | B9: 5 | C9: 4 | D9: 3 | E9: 2 | F9: 1 | H9: =((AVERAGE(G9:G12)-F9)/4)*100 -> #DIV/0! | J9: =AVERAGE(H9, H44, H56, H67, B84) -> #DIV/0!
A10: b. Grip of your hand that was most affected by your stroke? | B10: 5 | C10: 4 | D10: 3 | E10: 2 | F10: 1
A11: c. Leg that was most affected by your stroke? | B11: 5 | C11: 4 | D11: 3 | E11: 2 | F11: 1
A12: d. Foot/ankle that was most affected by your stroke? | B12: 5 | C12: 4 | D12: 3 | E12: 2 | F12: 1
A14: 2. In the past week, how difficult was it for you to... | B14: Not difficult at all | C14: A little difficult | D14: Somewhat difficult | E14: Very difficult | F14: Extremely difficult | G14: Score | H14: Scaled
A15: a. Remember things that people just told you? | B15: 5 | C15: 4 | D15: 3 | E15: 2 | F15: 1 | H15: =((AVERAGE(G15:G21)-F15)/4)*100 -> #DIV/0!
A16: b. Remember things that happened the day before? | B16: 5 | C16: 4 | D16: 3 | E16: 2 | F16: 1
A17: c. Remember to do things (e.g. keep scheduled appointments or take medication)? | B17: 5 | C17: 4 | D17: 3 | E17: 2 | F17: 1
A18: d. Remember the day of the week? | B18: 5 | C18: 4 | D18: 3 | E18: 2 | F18: 1
A19: e. Concentrate? | B19: 5 | C19: 4 | D19: 3 | E19: 2 | F19: 1
A20: f. Think quickly? | B20: 5 | C20: 4 | D20: 3 | E20: 2 | F20: 1
A21: g. Solve everyday problems? | B21: 5 | C21: 4 | D21: 3 | E21: 2 | F21: 1
A23: 3. In the past week, how often did you... | B23: None of the time | C23: A little of the time | D23: Some of the time | E23: Most of the time | F23: All of the time | G23: Score | H23: Scaled
A24: a. Feel sad? | B24: 5 | C24: 4 | D24: 3 | E24: 2 | F24: 1 | G24: 1 | H24: =((AVERAGE(G24:G28, G30, 6-G29, 6-G31, 6-G32)-F24)/4)*100 -> 0
A25: b. Feel that there is nobody you are close to? | B25: 5 | C25: 4 | D25: 3 | E25: 2 | F25: 1 | G25: 1
A26: c. Feel that you are a burden to others? | B26: 5 | C26: 4 | D26: 3 | E26: 2 | F26: 1 | G26: 1
A27: d. Feel that you have nothing to look forward to? | B27: 5 | C27: 4 | D27: 3 | E27: 2 | F27: 1 | G27: 1
A28: e. Blame yourself for mistakes that you made? | B28: 5 | C28: 4 | D28: 3 | E28: 2 | F28: 1 | G28: 1
A29: f. Enjoy things as much as ever? | B29: 5 | C29: 4 | D29: 3 | E29: 2 | F29: 1 | G29: 5
A30: g. Feel quite nervous? | B30: 5 | C30: 4 | D30: 3 | E30: 2 | F30: 1 | G30: 1
A31: h. Feel that life is worth living? | B31: 5 | C31: 4 | D31: 3 | E31: 2 | F31: 1 | G31: 5
A32: i. Smile and laugh at least once a day? | B32: 5 | C32: 4 | D32: 3 | E32: 2 | F32: 1 | G32: 5
A34: 4. In the past week, how difficult was it to... | B34: Not difficult at all | C34: A little difficult | D34: Somewhat difficult | E34: Very difficult | F34: Extremely difficult | G34: Score | H34: Scaled
A35: a. Say the name of someone who was in front of you? | B35: 5 | C35: 4 | D35: 3 | E35: 2 | F35: 1 | H35: =((AVERAGE(G35:G41)-F35)/4)*100 -> #DIV/0!
A36: b. Understand what was being said to you in a conversation? | B36: 5 | C36: 4 | D36: 3 | E36: 2 | F36: 1
A37: c. Reply to questions? | B37: 5 | C37: 4 | D37: 3 | E37: 2 | F37: 1
A38: d. Correctly name objects? | B38: 5 | C38: 4 | D38: 3 | E38: 2 | F38: 1
A39: e. Participate in a conversation with a group of people? | B39: 5 | C39: 4 | D39: 3 | E39: 2 | F39: 1
A40: f. Have a conversation on the telephone? | B40: 5 | C40: 4 | D40: 3 | E40: 2 | F40: 1
A41: g. Call another person on the telephone, including selecting the correct phone number and dialing? | B41: 5 | C41: 4 | D41: 3 | E41: 2 | F41: 1
A43: 5. In the past 2 weeks, how difficult was it to... | B43: Not difficult at all | C43: A little difficult | D43: Somewhat difficult | E43: Very difficult | F43: Could not do at all | G43: Score | H43: Scaled
A44: a. Cut your food with a knife and fork? | B44: 5 | C44: 4 | D44: 3 | E44: 2 | F44: 1 | H44: =((AVERAGE(G44:G53)-F44)/4)*100 -> #DIV/0!
A45: b. Dress the top part of your body? | B45: 5 | C45: 4 | D45: 3 | E45: 2 | F45: 1
A46: c. Bathe yourself? | B46: 5 | C46: 4 | D46: 3 | E46: 2 | F46: 1
A47: d. Clip your toenails? | B47: 5 | C47: 4 | D47: 3 | E47: 2 | F47: 1
A48: e. Get to the toilet on time? | B48: 5 | C48: 4 | D48: 3 | E48: 2 | F48: 1
...

Sheet 3_COPM
A1: Canadian Occupational Performance Measure (COPM)
A2: Full Form Template: | B2: https://uofu.app.box.com/file/2004642799198 | C2: Full Script | D2: https://uofu.app.box.com/file/1980825992620
A3: Patient ID: | B3: ='1_patient_info'!B3 -> ## | C3: Date: | D3: MM/DD/YYYY
A5: Time 1: Initial Assessment Date | B5: MM/DD/YYYY | C5: Time 2: Re-Assessment Date | D5: MM/DD/YYYY
A8: Scoring
A9: Item | B9: Ocupational Perfomance Problem (OPP) | C9: Importance | D9: Performance T1 | E9: Satisfaction T1 | F9: Performance T2 | G9: Satisfaction T2 | H9: Change in Performance (T2-T1) | I9: Change in Performance (T2-T1)2
A10: 1
A11: 2
A12: 3
A13: 4
A14: 5
A16: Total Score | B16: NA | C16: NA | D16: =SUM(D10:D14) -> 0 | E16: =SUM(E10:E14) -> 0 | F16: =SUM(F10:F14) -> 0 | G16: =SUM(G10:G14) -> 0 | H16: =SUM(H10:H14) -> 0 | I16: =SUM(I10:I14) -> 0
A17: Average Score | B17: NA | C17: NA | D17: =D16/5 -> 0 | E17: =E16/5 -> 0 | F17: =F16/5 -> 0 | G17: =G16/5 -> 0 | H17: =H16/5 -> 0 | I17: =I16/5 -> 0
A20: Self Care | B20: Comments | C20: Importance
A21: Personal Care
A24: Functional Mobility
A27: Community Management
A31: Productivity
A32: Paid or Unpaid work
A35: Household Management
A38: School and / or play
A43: Leisure
A44: Quiet recreation
A47: Active Recreation
A50: Socialization
A53: Notes and Observations
... A57: Re-assessment

Sheet 4_ModifiedAshworthScale
A1: Modified Ashworth Scale
A3: Patient ID: | B3: ='1_patient_info'!B3 -> ## | C3: Date: | D3: MM/DD/YYYY | E3: Side Assessed: | F3: ='1_patient_info'!B6 -> Right
A5: MAS Scoring Key: | D5: MMT Score Guide: | G5: AROM Scoring Key:
A6: 0 | B6: No increase in muscle tone | D6: 0/5 | E6: No Visible or palpable contraction | G6: Active Range of Motion, measured in degrees as quantified using goniometer.
A7: 1 | B7: Slight increase in tone (catch and release or minimal resistance at end of ROM) | D7: 1/5 | E7: Visible or palpable contraction (No ROM)
A8: 1+ | B8: Slight increase in tone (catch, followed by minimal resistance through < half of ROM) | D8: 2/5 | E8: Full ROM, gravity eliminated
A9: 2 | B9: More marked increase in tone through most of the ROM, but affected part(s) easily moved | D9: 3/5 | E9: Full ROM against gravity
A10: 3 | B10: Considerable increase in tone, passive movement difficult | D10: 4/5 | E10: Full ROM against gravity, moderate resistance
A11: 4 | B11: Affected part(s) rigid in flexion or extension | D11: 5/5 | E11: Normal Maximal Resistance
A13: Joint | B13: Muscle Group | C13: MAS Score | D13: MMT Score | E13: AROM
A14: Shoulder | B14: Flexors | C14: NT | D14: NT | E14: AROM in degrees OR NA | G14: NA = Not Applicable
A15: Shoulder | B15: Extensors | C15: NT | D15: NT | E15: AROM in degrees OR NA | G15: NT = Not Tested
A16: Shoulder | B16: Abductors | C16: NT | D16: NT | E16: AROM in degrees OR NA
A17: Elbow | B17: Flexors | C17: 0 | D17: #/5 or NA | E17: AROM in degrees OR NA
A18: Elbow | B18: Extensors | C18: 0 | D18: #/5 or NA | E18: AROM in degrees OR NA
A19: Wrist | B19: Wrist Flexors | C19: 0 | D19: #/5 or NA | E19: AROM in degrees OR NA
A20: Wrist | B20: Wrist Extensors | C20: 0 | D20: #/5 or NA | E20: AROM in degrees OR NA
A21: Fingers | B21: Finger Flexors | C21: 0 | D21: NT | E21: NT

Sheet 5_Fugl-Meyer
A1: Fugl-Meyer Assessment - Upper Extremity (FMA-UE)
A2: Full Manual (Official) | B2: https://uofu.app.box.com/file/1968584627441 | D2: Updated Manual: | E2: https://uofu.app.box.com/file/1989029623033
A3: Patient ID: | B3: ='1_patient_info'!B3 -> ## | C3: Date: | D3: MM/DD/YYYY | E3: Side Assessed: | F3: Right
A5: Scoring: | B5: 0 = Cannot perform | C5: 1 = Performs partially | D5: 2 = Performs fully
A7: Section | B7: Item | C7: Description | D7: Score Option | E7: Check Score | F7: Score Value (0 - 2)
A8: I. REFLEX ACTIVITY
A9: A1 | B9: Flexors: Biceps or finger reflex | C9: No Reflex | D9: 0
C10: Reflex Elicitable | D10: 2
A11: A2 | B11: Extensors: Triceps reflex | C11: No Reflex | D11: 0
C12: Reflex Elicitable | D12: 2 | H12: Max Score: 66
A13: II. SYNERGISTIC MOVMENT: FLEXOR SYNERGY | H13: TOTAL SCORE: | I13: =SUM(F9:F61, F63:F114) -> 0
A14: A3 | B14: Shoulder girdle retraction | C14: No Visible or Palpable Retraction | D14: 0
C15: Partly Done | D15: 1
C16: Faultless | D16: 2
A17: A4 | B17: Shoulder girdle elevation | C17: No Visible or Palpable Retraction | D17: 0
C18: Partly Done | D18: 1
C19: Faultless | D19: 2
A20: A5 | B20: Shoulder abduction | C20: No Visible or Palpable Retraction | D20: 0
C21: Partly Done | D21: 1
C22: Faultless | D22: 2
A23: A6 | B23: Shoulder external rotation | C23: No Visible or Palpable Retraction | D23: 0
C24: Partly Done | D24: 1
C25: Faultless | D25: 2
A26: A7 | B26: Elbow Flexion | C26: No Visible or Palpable Retraction | D26: 0
C27: Partly Done | D27: 1
C28: Faultless | D28: 2
A29: A8 | B29: Forearm supination | C29: No Visible or Palpable Retraction | D29: 0
C30: Partly Done | D30: 1
C31: Faultless | D31: 2
A32: III. SYNERGISTIC MOVMENT: EXTENSOR SYNERGY
A33: A9 | B33: Shoulder adduction / internal rotation | C33: Not done at all | D33: 0
C34: Partly Done | D34: 1
C35: Faultless | D35: 2
A36: A10 | B36: Elbow Extension | C36: Not done at all | D36: 0
C37: Partly Done | D37: 1
C38: Faultless | D38: 2
A39: A11 | B39: Forearm pronation | C39: Not done at all | D39: 0
C40: Partly Done | D40: 1
C41: Faultless | D41: 2
A42: IV: MOVEMENT COMBINING SYNERGY
...

Sheet 6_box_and_blocks
A1: Box and Blocks Test | B1: https://uofu.app.box.com/file/1971344564741
A3: Patient ID: | B3: ='1_patient_info'!B3 -> ## | C3: Date: | D3: MM/DD/YYYY
A4: Affected Hand: | B4: ='1_patient_info'!B6 -> Right
A6: Scoring: | B6: The score is the number of blocks transported in one minute. There are 150 blocks.
A8: WITHOUT MYOPRO
A9: Date | B9: Hand | C9: Trial Type | D9: Score (# of blocks) | E9: Notes
A10: MM/DD/YYYY | B10: Right | C10: Standard 60s
A11: MM/DD/YYYY | B11: Left | C11: Standard 60s
A13: WITH MYOPRO
A14: Date | B14: Hand | C14: Trial Type | D14: Score (# of blocks) | E14: Notes
A15: MM/DD/YYYY | B15: Right | C15: Standard 60s
A16: MM/DD/YYYY | B16: Left | C16: Standard 60s

Sheet 7a_MyomoTasks_WITHOUT_MYOPRO
A1: Myomo Functional Tasks (WITHOUT MYOPRO)
A3: Patient ID: | B3: ='1_patient_info'!B3 -> ## | C3: Date: | D3: MM/DD/YYYY
A6: Task 1: Move Object to Mouth | C6: WITHOUT MyoPro
A7: Component # | B7: Name | C7: Achieve? | D7: Time [sec]
A8: 1 | B8: Starting Position | C8: 0
A9: 2 | B9: Grasp | C9: 0
A10: 3 | B10: Cut Pickle | C10: 0
A11: 4 | B11: To Mouth | C11: 0
A12: 5 | B12: Ending Position | C12: 0
B13: SUM | C13: =SUM(C8:C12) -> 0 | D13: =SUM(D8:D12) -> 0
A15: Task 2: Hold Object in Space | C15: WITHOUT MyoPro
A16: Component # | B16: Name | C16: Achieve? | D16: Time [sec]
A17: 1 | B17: Starting Position | C17: 0
A18: 2 | B18: Grasp | C18: 0
A19: 3 | B19: Lift Bag | C19: 0
A20: 4 | B20: Ending Position | C20: 0
B21: SUM | C21: =SUM(C17:C20) -> 0 | D21: =SUM(D17:D20) -> 0
A23: Task 3: Stablize Object | C23: WITHOUT MyoPro
A24: Component # | B24: Name | C24: Achieve? | D24: Time [sec]
A25: 1 | B25: Starting Position | C25: 0
A26: 2 | B26: Grasp | C26: 0
A27: 3 | B27: Stabilize Bowl | C27: 0
A28: 4 | B28: Ending Position | C28: 0
B29: SUM | C29: =SUM(C25:C28) -> 0 | D29: =SUM(D25:D28) -> 0
A31: Task 4: Move Object (Towel) to New Location | C31: WITHOUT MyoPro
A32: Component # | B32: Name | C32: Achieve? | D32: Time [sec]
A33: 1 | B33: Starting Position | C33: 0
A34: 2 | B34: Grasp | C34: 0
A35: 3 | B35: Move Towel | C35: 0
A36: 4 | B36: Ending Position | C36: 0
B37: SUM | C37: =SUM(C33:C36) -> 0 | D37: =SUM(D33:D36) -> 0
A39: Task 5: Water Bottle – Stabilize Object | C39: WITHOUT MyoPro
A40: Component # | B40: Name | C40: Achieve? | D40: Time [sec]
A41: 1 | B41: Starting Position | C41: 0
A42: 2 | B42: Grasp | C42: 0
A43: 3 | B43: Move Towel | C43: 0
A44: 4 | B44: Ending Position | C44: 0
B45: SUM | C45: =SUM(C41:C44) -> 0 | D45: =SUM(D41:D44) -> 0
A47: Task 6: Laundry Basket – Lift and Move Object to a new location | B47: WITHOUT MyoPro
A48: Name | B48: Achieve? | C48: Time [sec]
...

Sheet 7b_MyomoTasks_WITH_MYOPRO
A1: Myomo Functional Tasks (WITH MYOPRO)
A3: Patient ID: | B3: ='1_patient_info'!B3 -> ## | C3: Date: | D3: MM/DD/YYYY
A6: Task 1: Move Object to Mouth | C6: WITH MyoPro
A7: Component # | B7: Name | C7: Achieve? | D7: Time [sec]
A8: 1 | B8: Starting Position | C8: 0
A9: 2 | B9: Grasp | C9: 0
A10: 3 | B10: Cut Pickle | C10: 0
A11: 4 | B11: To Mouth | C11: 0
A12: 5 | B12: Ending Position | C12: 0
B13: SUM | C13: =SUM(C8:C12) -> 0 | D13: =SUM(D8:D12) -> 0
A15: Task 2: Hold Object in Space | C15: WITH MyoPro
A16: Component # | B16: Name | C16: Achieve? | D16: Time [sec]
A17: 1 | B17: Starting Position | C17: 0
A18: 2 | B18: Grasp | C18: 0
A19: 3 | B19: Lift Bag | C19: 0
A20: 4 | B20: Ending Position | C20: 0
B21: SUM | C21: =SUM(C17:C20) -> 0 | D21: =SUM(D17:D20) -> 0
A23: Task 3: Stablize Object | C23: WITH MyoPro
A24: Component # | B24: Name | C24: Achieve? | D24: Time [sec]
A25: 1 | B25: Starting Position | C25: 0
A26: 2 | B26: Grasp | C26: 0
A27: 3 | B27: Stabilize Bowl | C27: 0
A28: 4 | B28: Ending Position | C28: 0
B29: SUM | C29: =SUM(C25:C28) -> 0 | D29: =SUM(D25:D28) -> 0
A31: Task 4: Move Object (Towel) to New Location | C31: WITH MyoPro
A32: Component # | B32: Name | C32: Achieve? | D32: Time [sec]
A33: 1 | B33: Starting Position | C33: 0
A34: 2 | B34: Grasp | C34: 0
A35: 3 | B35: Move Towel | C35: 0
A36: 4 | B36: Ending Position | C36: 0
B37: SUM | C37: =SUM(C33:C36) -> 0 | D37: =SUM(D33:D36) -> 0
A39: Task 5: Water Bottle – Stabilize Object | C39: WITH MyoPro
A40: Component # | B40: Name | C40: Achieve? | D40: Time [sec]
A41: 1 | B41: Starting Position | C41: 0
A42: 2 | B42: Grasp | C42: 0
A43: 3 | B43: Move Towel | C43: 0
A44: 4 | B44: Ending Position | C44: 0
B45: SUM | C45: =SUM(C41:C44) -> 0 | D45: =SUM(D41:D44) -> 0
A47: Task 6: Laundry Basket – Lift and Move Object to a new location | B47: WITH MyoPro
A48: Name | B48: Achieve? | C48: Time [sec]
...

Sheet 8a_CAHAI_WITHOUT_MYOPRO
A1: Chedoke Arm and Hand Activity Inventory (CAHAI-13) (WITHOUT MYOPRO)
A2: Full Manual: | B2: https://uofu.app.box.com/file/1971346843081 | C2: Scoring Sheet (PDF): | D2: https://uofu.app.box.com/file/1971345419750
A3: Patient ID: | B3: ='1_patient_info'!B3 -> ## | C3: Date: | D3: MM/DD/YYYY | E3: Affected Limb: | F3: ='1_patient_info'!B6 -> Right
A5: Activity Scale Key
A6: 1 | B6: Total assist (weak U/L < 25%)
A7: 2 | B7: Maximal assist (weak U/L = 25-49%)
A8: 3 | B8: Moderate assist (weak U/L = 50-74%)
A9: 4 | B9: Minimal assist (weak U/L > 75%)
A10: 5 | B10: Supervision
A11: 6 | B11: Modified independence (device)
A12: 7 | B12: Complete independence (timely, safely)
A13: Note: You can change the role using the dropdowns in each cell
A14: # | B14: Task | C14: Role of Affected Arm | D14: Score (1-7) | E14: Comments
A15: 1 | B15: Open jar of coffee | C15: holds jar | D15: 1 | G15: General Comment
A16: 2 | B16: Call 911 | C16: holds receiver and dials phone | D16: 1
A17: 3 | B17: Draw a line with a ruler | C17: holds ruler | D17: 1
A18: 4 | B18: Pour a glass of water | C18: holds glass | D18: 1
A19: 5 | B19: Wring out washcloth | C19: Bilateral Task | D19: 1
A20: 6 | B20: Do up five buttons | C20: Bilateral Task | D20: 1
A21: 7 | B21: Dry back with towel | C21: grasps towel end | D21: 1
A22: 8 | B22: Put toothpaste on toothbrush | C22: holds toothpaste | D22: 1
A23: 9 | B23: Cut medium resistance putty | C23: holds fork | D23: 1
A24: 10 | B24: Zip up the zipper | C24: holds zipper pull | D24: 1
A25: 11 | B25: Clean a pair of eyeglasses | C25: holds glasses | D25: 1
A26: 12 | B26: Place container on table | C26: Unilateral Task | D26: 1
A27: 13 | B27: Carry bag upstairs | C27: Unilateral Task | D27: 1
C29: Total Score (out of 91): | D29: =SUM(D15:D27) -> 13 | E29: /91

Sheet 8b_CAHAI_WITH_MYOPRO
A1: Chedoke Arm and Hand Activity Inventory (CAHAI-13) (WITH MYOPRO)
A2: Full Manual: | B2: https://uofu.app.box.com/file/1971346843081 | C2: Scoring Sheet (PDF): | D2: https://uofu.app.box.com/file/1971345419750
A3: Patient ID: | B3: ='1_patient_info'!B3 -> ## | C3: Date: | D3: MM/DD/YYYY | E3: Affected Limb: | F3: ='1_patient_info'!B6 -> Right
A5: Activity Scale Key
A6: 1 | B6: Total assist (weak U/L < 25%)
A7: 2 | B7: Maximal assist (weak U/L = 25-49%)
A8: 3 | B8: Moderate assist (weak U/L = 50-74%)
A9: 4 | B9: Minimal assist (weak U/L > 75%)
A10: 5 | B10: Supervision
A11: 6 | B11: Modified independence (device)
A12: 7 | B12: Complete independence (timely, safely)
A13: Note: You can change the role using the dropdowns in each cell
A14: # | B14: Task | C14: Role of Affected Arm | D14: Score (1-7) | E14: Comments
A15: 1 | B15: Open jar of coffee | C15: holds jar | D15: 1 | G15: General Comment
A16: 2 | B16: Call 911 | C16: holds receiver and dials phone | D16: 1
A17: 3 | B17: Draw a line with a ruler | C17: holds ruler | D17: 1
A18: 4 | B18: Pour a glass of water | C18: holds glass | D18: 1
A19: 5 | B19: Wring out washcloth | C19: Bilateral Task | D19: 1
A20: 6 | B20: Do up five buttons | C20: Bilateral Task | D20: 1
A21: 7 | B21: Dry back with towel | C21: grasps towel end | D21: 1
A22: 8 | B22: Put toothpaste on toothbrush | C22: holds toothpaste | D22: 1
A23: 9 | B23: Cut medium resistance putty | C23: holds fork | D23: 1
A24: 10 | B24: Zip up the zipper | C24: holds zipper pull | D24: 1
A25: 11 | B25: Clean a pair of eyeglasses | C25: holds glasses | D25: 1
A26: 12 | B26: Place container on table | C26: Unilateral Task | D26: 1
A27: 13 | B27: Carry bag upstairs | C27: Unilateral Task | D27: 1
C29: Total Score (out of 91): | D29: =SUM(D15:D27) -> 13 | E29: /91

Sheet 9a_NASA_TLX_WITHOUT_MYOPRO
A1: NASA TASK LOAD INDEX Scoring (WITHOUT MYOPRO)
A4: Patient ID: | B4: ='1_patient_info'!B3 -> ## | C4: Date: | D4: MM/DD/YYYY
A8: Rate on a scale of 0-20
A10: Mental Demand | B10: 0
A12: Physical Demand | B12: 0
A14: Temporal Demand | B14: 0
A16: Performance | B16: 0
A18: Effort | B18: 0
A20: Frustration | B20: 0

Sheet 9b_NASA_TLX_WITH_MYOPRO
A1: NASA TASK LOAD INDEX Scoring (WITH MYOPRO)
A4: Patient ID: | B4: ='1_patient_info'!B3 -> ## | C4: Date: | D4: MM/DD/YYYY
A8: Rate on a scale of 0-20
A10: Mental Demand | B10: 0
A12: Physical Demand | B12: 0
A14: Temporal Demand | B14: 0
A16: Performance | B16: 0
A18: Effort | B18: 0
A20: Frustration | B20: 0
